2018-09-30 17:45:37,908 - INFO - Бот запускается
2018-09-30 17:46:07,316 - INFO - Received signal 2 (SIGINT), stopping...
2018-09-30 17:46:11,639 - ERROR - Exception during reset or similar
Traceback (most recent call last):
  File "/Users/riokko/Projects/Z-chat/env/lib/python3.6/site-packages/sqlalchemy/pool.py", line 709, in _finalize_fairy
    fairy._reset(pool)
  File "/Users/riokko/Projects/Z-chat/env/lib/python3.6/site-packages/sqlalchemy/pool.py", line 880, in _reset
    pool._dialect.do_rollback(self)
  File "/Users/riokko/Projects/Z-chat/env/lib/python3.6/site-packages/sqlalchemy/engine/default.py", line 459, in do_rollback
    dbapi_connection.rollback()
sqlite3.ProgrammingError: SQLite objects created in a thread can only be used in that same thread. The object was created in thread id 123145390551040 and this is thread id 4752274880.
2018-09-30 17:46:11,644 - ERROR - Exception closing connection <sqlite3.Connection object at 0x10edb18f0>
Traceback (most recent call last):
  File "/Users/riokko/Projects/Z-chat/env/lib/python3.6/site-packages/sqlalchemy/pool.py", line 709, in _finalize_fairy
    fairy._reset(pool)
  File "/Users/riokko/Projects/Z-chat/env/lib/python3.6/site-packages/sqlalchemy/pool.py", line 880, in _reset
    pool._dialect.do_rollback(self)
  File "/Users/riokko/Projects/Z-chat/env/lib/python3.6/site-packages/sqlalchemy/engine/default.py", line 459, in do_rollback
    dbapi_connection.rollback()
sqlite3.ProgrammingError: SQLite objects created in a thread can only be used in that same thread. The object was created in thread id 123145390551040 and this is thread id 4752274880.

During handling of the above exception, another exception occurred:

Traceback (most recent call last):
  File "/Users/riokko/Projects/Z-chat/env/lib/python3.6/site-packages/sqlalchemy/pool.py", line 314, in _close_connection
    self._dialect.do_close(connection)
  File "/Users/riokko/Projects/Z-chat/env/lib/python3.6/site-packages/sqlalchemy/engine/default.py", line 465, in do_close
    dbapi_connection.close()
sqlite3.ProgrammingError: SQLite objects created in a thread can only be used in that same thread. The object was created in thread id 123145390551040 and this is thread id 4752274880.
